Workbook

Sheet 日当整理表（農・維）
B1: 日当等整理帳 | E1: 令和7年度 農地維持支払い一覧表 | O1: NO. | P1: １－１
B3: 農地維持支払 | E3: ○ | G3: 活動内容 | I3: ： | J3: 畦畔・農道・路肩・法面の草刈り等
B4: 資源向上支払（共同活動） | G4: 活動日時 | I4: ： | J4: 別紙作業表による
B5: 資源向上支払（長寿命化） | G5: 参加者数 | I5: ： | J5: １法人・1団体・個人２名
B8: 参加者一覧 兼 領収印
B9: No | C9: 氏名 | D9: 作業時間帯 | G9: 実働時間(H) | H9: 借用機材 | M9: 支払額 （円） | Q9: 領収印
H10: 軽トラ | I10: 草刈機 | J10: 畦畔草刈機 | K10: 動力噴霧器 | M10: 日当 | N10: 機械経費 | O10: その他 | P10: 合計 | R10: 整理表ＮＯ
B11: 1 | C11: （農）法人カマタ | D11: 別紙作業表による | G11: 143 | I11: ○ | J11: ○ | K11: ○ | M11: =法人一覧!AC57 -> 143000 | N11: =法人一覧!AC58+法人一覧!AC59+法人一覧!AC60 -> 67850 | P11: =SUM(M11:O11) -> 210850 | Q11: 振込 | R11: 農・維 1－1/2
B12: 2 | C12: （農）法人カマタ | E12: 〃 | G12: 138 | I12: ○ | J12: ○ | K12: ○ | M12: =法人一覧!AC131 -> 138000 | N12: =法人一覧!AC132+法人一覧!AC133+法人一覧!AC134 -> 66750 | P12: =SUM(M12:O12) -> 204750 | Q12: 振込 | R12: 農・維 １－2/2
B13: 3 | C13: 藤井 守 | D13: 別紙作業表による | G13: 63 | I13: ○ | J13: ○ | K13: ○ | M13: 63000 | N13: 30600 | P13: =SUM(M13:O13) -> 93600 | Q13: → | R13: 農・維 ２
B14: 4 | C14: 阿部 正隆 | D14: 別紙作業表による | G14: 78 | I14: ○ | J14: ○ | K14: ○ | M14: 78000 | N14: =阿部正隆!Y34 -> 35400 | P14: =SUM(M14:O14) -> 113400 | Q14: → | R14: 農・維 3
B15: 5 | C15: 斉木 忠義 | D15: 別紙作業表による | G15: 10 | I15: ○ | K15: ○ | M15: 10000 | N15: 3500 | P15: =SUM(M15:O15) -> 13500 | Q15: → | R15: 農・維 ４
B16: 6 | C16: 鎌田下管理組合 | D16: 別紙作業表による | G16: 27 | I16: ○ | K16: ○ | M16: =下管理組合!R33 -> 27000 | N16: =下管理組合!R34+下管理組合!R36 -> 5950 | P16: =SUM(M16:O16) -> 32950 | Q16: 振込 | R16: 農・維 ５
B18: 合 計 | G18: =SUM(G11:G16) -> 459 | M18: =SUM(M11:M16) -> 459000 | N18: =SUM(N11:N16) -> 210050 | P18: =SUM(P11:P16) -> 669050

Sheet 法人一覧
B1: 日当等整理表 | F1: 農地維持
D2: 農道・畦畔・水路部分の草刈り作業 | M2: (農）法人カマタ | O2: １/２ | Q2: 令和7年度 | AB2: 農・維１-１/２ | AG2: =AD57+AD131+#REF! -> #REF!
B3: 参加者一覧 兼 領収印 | AG3: 451573
C4: 氏 名 | D4: NO. | E4: 1 | F4: 2 | G4: 3 | H4: 4 | I4: 5 | J4: 6 | K4: 7 | L4: 8 | M4: 9 | N4: 10 | O4: 11 | P4: 12 | Q4: 13 | R4: 14 | S4: 15 | T4: 16 | U4: 17 | V4: 18 | W4: 19 | X4: 20 | Y4: 21 | Z4: 22 | AA4: 23 | AB4: 計 | AC4: 小 計 | AD4: 合 計 | AE4: 領 収 印 | AG4: =AG2-AG3 -> #REF!
D5: 日 付 | E5: 4/5 | F5: 4/12 | G5: 4/13 | H5: 4/19 | I5: 4/20 | J5: 4/26 | K5: 4/27 | L5: 5/3 | M5: 5/5 | N5: 5/6 | O5: 6/1 | P5: 6/3 | Q5: 6/14 | R5: 6/22 | S5: 6/28 | T5: 7/5 | U5: 7/19 | V5: 7/21 | W5: 7/22 | X5: 8/16 | Y5: 8/23 | Z5: 8/31 | AA5: 9/6
D6: 時 間 帯 | E6: 0.33333333 | F6: 0.29166667 | G6: 0.33333333 | H6: 0.33333333 | I6: 0.33333333 | J6: 0.29166667 | K6: 0.33333333 | L6: 0.29166667 | M6: 0.29166667 | N6: 0.33333333 | O6: 0.625 | P6: 0.33333333 | Q6: 0.29166667 | R6: 0.33333333 | S6: 0.58333333 | T6: 0.66666667 | U6: 16：：00 | V6: 0.625 | W6: 0.66666667 | X6: 0.70833333 | Y6: 0.66666667 | Z6: 0.33333333 | AA6: 0.33333333
E7: ～ | F7: ～ | G7: ～ | H7: ～ | I7: ～ | J7: ～ | K7: ～ | L7: ～ | M7: ～ | N7: ～ | O7: ～ | P7: ～ | Q7: ～ | R7: ～ | S7: ～ | T7: ～ | U7: ～ | V7: ～ | W7: ～ | X7: ～ | Y7: ～ | Z7: ～ | AA7: ～
E8: 0.41666667 | F8: 0.375 | G8: 0.41666667 | H8: 0.41666667 | I8: 0.375 | J8: 0.375 | K8: 0.41666667 | L8: 0.33333333 | M8: 0.375 | N8: 0.41666667 | O8: 0.66666667 | P8: 0.41666667 | Q8: 0.375 | R8: 0.41666667 | S8: 0.66666667 | T8: 0.75 | U8: 0.70833333 | V8: 0.70833333 | W8: 0.75 | X8: 0.75 | Y8: 0.75 | Z8: 0.41666667 | AA8: 0.45833333
D9: 実働時間 | E9: 2 | F9: 2 | G9: 2 | H9: 2 | I9: 1 | J9: 2 | K9: 2 | L9: 1 | M9: 2 | N9: 2 | O9: 1 | P9: 2 | Q9: 2 | R9: 2 | S9: 2 | T9: 2 | U9: 1 | V9: 2 | W9: 2 | X9: 1 | Y9: 2 | Z9: 2 | AA9: 3 | AB9: =SUM(E9:AA9) -> 42
D10: 活動内容 | E10: 草刈り | F10: 草刈り | G10: 草刈り | H10: 草刈り | I10: 草刈り | J10: 草刈り | K10: 草刈り | L10: 草刈り | M10: 草刈り | N10: 草刈り | O10: 草刈り | P10: 草刈り | Q10: 草刈り | R10: 草刈り | S10: 草刈り | T10: 除草剤 散布 | U10: 除草剤 散布 | V10: 除草剤 散布 | W10: 除草剤 散布 | X10: 除草剤 散布 | Y10: 除草剤 散布 | Z10: 草刈り | AA10: 草刈り
B11: 1 | C11: 齋木 太郎 | D11: 日 当 | E11: 2000 | F11: 2000 | G11: 2000 | H11: 2000 | I11: 1000 | J11: 2000 | K11: 2000 | L11: 1000 | M11: 2000 | N11: 2000 | O11: 1000 | P11: 2000 | Q11: 2000 | R11: 2000 | S11: 2000 | T11: 2000 | U11: 1000 | V11: 2000 | W11: 2000 | X11: 1000 | Y11: 2000 | Z11: 2000 | AA11: 3000 | AC11: =SUM(E11:AB11) -> 42000 | AD11: =AC11+AC12+AC13+AC14+AC15 -> 61450
D12: 草 刈 機 | E12: 700 | G12: 700 | H12: 700 | J12: 350 | K12: 700 | M12: 700 | N12: 700 | O12: 350 | P12: 700 | Q12: 350 | R12: 700 | W12: 700 | Z12: 700 | AA12: 700 | AC12: =SUM(E12:AB12) -> 8750
D13: 畦畔草刈機 | F13: 1600 | I13: 800 | J13: 800 | L13: 800 | Q13: 800 | S13: 1600 | AA13: 800 | AC13: =SUM(E13:AB13) -> 7200
D14: 動力噴霧器 | T14: 700 | U14: 350 | V14: 700 | W14: 700 | X14: 350 | Y14: 700 | AC14: =SUM(E14:AB14) -> 3500
D15: 軽トラック | AC15: =SUM(E15:AB15) -> 0
C17: 氏 名 | D17: NO. | E17: 1 | F17: 2 | G17: 3 | H17: 4 | I17: 5 | J17: 6 | K17: 7 | L17: 8 | M17: 9 | N17: 10 | O17: 11 | P17: 12 | Q17: 13 | R17: 14 | S17: 15 | T17: 16 | U17: 17 | V17: 18 | W17: 19 | X17: 20 | Y17: 21 | Z17: 22 | AA17: 23 | AB17: 計 | AC17: 小 計 | AD17: 合 計 | AE17: 領 収 印
D18: 日 付 | E18: 4/5 | F18: 4/8 | G18: 4/13 | H18: 4/15 | I18: 4/20 | J18: 5/2 | K18: 5/4 | L18: 5/6 | M18: 6/1 | N18: 6/3 | O18: 6/15 | P18: 7/5 | Q18: 7/8 | R18: 7/12 | S18: 7/15 | T18: 8/3 | U18: 8/11 | V18: 8/30 | W18: 9/7 | X18: 9/8
D19: 時 間 帯 | E19: 0.33333333 | F19: 0.33333333 | G19: 0.625 | H19: 0.33333333 | I19: 0.29166667 | J19: 0.33333333 | K19: 0.625 | L19: 0.33333333 | M19: 0.33333333 | N19: 0.33333333 | O19: 0.33333333 | P19: 0.66666667 | Q19: 0.66666667 | R19: 0.66666667 | S19: 0.66666667 | T19: 0.625 | U19: 0.29166667 | V19: 0.29166667 | W19: 0.33333333 | X19: 0.625
E20: ～ | F20: ～ | G20: ～ | H20: ～ | I20: ～ | J20: ～ | K20: ～ | L20: ～ | M20: ～ | N20: ～ | O20: ～ | P20: ～ | Q20: ～ | R20: ～ | S20: ～ | T20: ～ | U20: ～ | V20: ～ | W20: ～ | X20: ～
E21: 0.41666667 | F21: 0.41666667 | G21: 0.70833333 | H21: 0.41666667 | I21: 0.375 | J21: 0.41666667 | K21: 0.70833333 | L21: 0.41666667 | M21: 0.41666667 | N21: 0.41666667 | O21: 0.41666667 | P21: 0.75 | Q21: 0.70833333 | R21: 0.70833333 | S21: 0.75 | T21: 0.66666667 | U21: 0.375 | V21: 0.375 | W21: 0.41666667 | X21: 0.70833333
D22: 実働時間 | E22: 2 | F22: 2 | G22: 2 | H22: 2 | I22: 2 | J22: 2 | K22: 2 | L22: 2 | M22: 2 | N22: 2 | O22: 2 | P22: 2 | Q22: 1 | R22: 1 | S22: 2 | T22: 1 | U22: 2 | V22: 2 | W22: 2 | X22: 2 | AB22: =SUM(E22:AA22) -> 37
D23: 活動内容 | E23: 草刈り | F23: 草刈り | G23: 草刈り | H23: 草刈り | I23: 草刈り | J23: 草刈り | K23: 草刈り | L23: 草刈り | M23: 草刈り | N23: 草刈り | O23: 草刈り | P23: 除草剤 散布 | Q23: 除草剤 散布 | R23: 除草剤 散布 | S23: 除草剤 散布 | T23: 草刈り | U23: 草刈り | V23: 草刈り | W23: 草刈り | X23: 草刈り
B24: 2 | C24: 阿部賢二 | D24: 日 当 | E24: 2000 | F24: 2000 | G24: 2000 | H24: 2000 | I24: 2000 | J24: 2000 | K24: 2000 | L24: 2000 | M24: 2000 | N24: 2000 | O24: 2000 | P24: 2000 | Q24: 1000 | R24: 1000 | S24: 2000 | T24: 1000 | U24: 2000 | V24: 2000 | W24: 2000 | X24: 2000 | AC24: =SUM(E24:AB24) -> 37000 | AD24: =AC24+AC25+AC26+AC27+AC28 -> 54900
D25: 草 刈 機 | E25: 700 | H25: 700 | I25: 700 | J25: 700 | K25: 700 | L25: 700 | N25: 350 | O25: 700 | T25: 350 | U25: 700 | X25: 700 | AC25: =SUM(E25:AB25) -> 7000
D26: 畦畔草刈機 | F26: 1600 | G26: 1600 | M26: 1600 | N26: 800 | V26: 1600 | W26: 1600 | AC26: =SUM(E26:AB26) -> 8800
D27: 動力噴霧器 | P27: 700 | Q27: 350 | R27: 350 | S27: 700 | AC27: =SUM(E27:AB27) -> 2100
D28: 軽トラック | AC28: =SUM(E28:AB28) -> 0
C30: 氏 名 | D30: NO. | E30: 1 | F30: 2 | G30: 3 | H30: 4 | I30: 5 | J30: 6 | K30: 7 | L30: 8 | M30: 9 | N30: 10 | O30: 11 | P30: 12 | Q30: 13 | R30: 14 | S30: 15 | T30: 16 | U30: 17 | V30: 18 | W30: 19 | X30: 20 | Y30: 21 | Z30: 22 | AA30: 23 | AB30: 計 | AC30: 小 計 | AD30: 合 計 | AE30: 領 収 印
D31: 日 付 | E31: 4/5 | F31: 4/8 | G31: 4/10 | H31: 4/14 | I31: 4/23 | J31: 4/30 | K31: 5/3 | L31: 5/5 | M31: 5/7 | N31: 5/9 | O31: 6/2 | P31: 6/5 | Q31: 6/15 | R31: 7/2 | S31: 7/4 | T31: 7/19 | U31: 8/10 | V31: 8/14 | W31: 8/17
D32: 時 間 帯 | E32: 0.33333333 | F32: 0.33333333 | G32: 0.33333333 | H32: 0.33333333 | I32: 0.29166667 | J32: 0.33333333 | K32: 0.29166667 | L32: 0.33333333 | M32: 0.33333333 | N32: 0.29166667 | O32: 0.33333333 | P32: 0.33333333 | Q32: 0.29166667 | R32: 0.66666667 | S32: 0.66666667 | T32: 0.66666667 | U32: 0.33333333 | V32: 0.33333333 | W32: 0.33333333
E33: ～ | F33: ～ | G33: ～ | H33: ～ | I33: ～ | J33: ～ | K33: ～ | L33: ～ | M33: ～ | N33: ～ | O33: ～ | P33: ～ | Q33: ～ | R33: ～ | S33: ～ | T33: ～ | U33: ～ | V33: ～ | W33: ～
E34: 0.41666667 | F34: 0.375 | G34: 0.41666667 | H34: 0.41666667 | I34: 0.375 | J34: 0.41666667 | K34: 0.375 | L34: 0.41666667 | M34: 0.41666667 | N34: 0.375 | O34: 0.375 | P34: 0.41666667 | Q34: 0.375 | R34: 0.75 | S34: 0.75 | T34: 0.75 | U34: 0.41666667 | V34: 0.41666667 | W34: 0.41666667
D35: 実働時間 | E35: 2 | F35: 1 | G35: 2 | H35: 2 | I35: 2 | J35: 2 | K35: 2 | L35: 2 | M35: 2 | N35: 2 | O35: 1 | P35: 2 | Q35: 2 | R35: 2 | S35: 2 | T35: 2 | U35: 2 | V35: 2 | W35: 2 | AB35: =SUM(E35:AA35) -> 36
D36: 活動内容 | E36: 草刈り | F36: 草刈り | G36: 草刈り | H36: 草刈り | I36: 草刈り | J36: 草刈り | K36: 草刈り | L36: 草刈り | M36: 草刈り | N36: 草刈り | O36: 草刈り | P36: 草刈り | Q36: 草刈り | R36: 除草剤 散布 | S36: 除草剤 散布 | T36: 除草剤 散布 | U36: 草刈り | V36: 草刈り | W36: 草刈り
B37: 3 | C37: 嘉藤 茂 | D37: 日 当 | E37: 2000 | F37: 1000 | G37: 2000 | H37: 2000 | I37: 2000 | J37: 2000 | K37: 2000 | L37: 2000 | M37: 2000 | N37: 2000 | O37: 1000 | P37: 2000 | Q37: 2000 | R37: 2000 | S37: 2000 | T37: 2000 | U37: 2000 | V37: 2000 | W37: 2000 | AC37: =SUM(E37:AB37) -> 36000 | AD37: =AC37+AC38+AC39+AC40+AC41 -> 54000
D38: 草 刈 機 | E38: 700 | F38: 350 | H38: 700 | J38: 700 | L38: 700 | M38: 700 | O38: 350 | P38: 700 | V38: 700 | W38: 700 | AC38: =SUM(E38:AB38) -> 6300
D39: 畦畔草刈機 | G39: 1600 | I39: 1600 | K39: 1600 | N39: 1600 | Q39: 1600 | U39: 1600 | AC39: =SUM(E39:AB39) -> 9600
D40: 動力噴霧器 | R40: 700 | S40: 700 | T40: 700 | AC40: =SUM(E40:AB40) -> 2100
D41: 軽トラック | AC41: =SUM(E41:AB41) -> 0
C43: 氏 名 | D43: NO. | E43: 1 | F43: 2 | G43: 3 | H43: 4 | I43: 5 | J43: 6 | K43: 7 | L43: 8 | M43: 9 | N43: 10 | O43: 11 | P43: 12 | Q43: 13 | R43: 14 | S43: 15 | T43: 16 | U43: 17 | V43: 18 | W43: 19 | X43: 20 | Y43: 21 | Z43: 22 | AA43: 23 | AB43: 計 | AC43: 小 計 | AD43: 合 計 | AE43: 領 収 印
...

Sheet Sheet11
B1: 日当等整理表
B3: 参加者一覧 兼 領収印
C4: 氏 名 | D4: NO. | E4: 1 | F4: 2 | G4: 3 | H4: 4 | I4: 5 | J4: 6 | K4: 7 | L4: 8 | M4: 9 | N4: 10 | O4: 11 | P4: 12 | Q4: 13 | R4: 14 | S4: 15 | T4: 16 | U4: 17 | V4: 18 | W4: 19 | X4: 20 | Y4: 21 | Z4: 22 | AA4: 23 | AB4: 24 | AC4: 25 | AD4: 26 | AE4: 小 計 | AF4: 合 計 | AG4: 領 収 印
D5: 日 付
D6: 時 間 帯
E7: ～ | F7: ～ | G7: ～ | H7: ～ | I7: ～ | J7: ～ | K7: ～ | L7: ～ | M7: ～ | N7: ～ | O7: ～ | P7: ～ | Q7: ～ | R7: ～ | S7: ～ | T7: ～ | U7: ～ | V7: ～ | W7: ～ | X7: ～ | Y7: ～ | Z7: ～ | AA7: ～ | AB7: ～ | AC7: ～ | AD7: ～
D9: 実働時間
D10: 活動内容
B11: 1 | C11: 斉木 裕司 | D11: 日 当 | AE11: =SUM(E11:AD11) -> 0 | AF11: =AE11+AE12+AE13+AE14+AE15 -> 0
D12: 草 刈 機 | AE12: =SUM(E12:AD12) -> 0
D13: 畦畔草刈機 | AE13: =SUM(E13:AD13) -> 0
D14: 法面草刈機 | AE14: =SUM(E14:AD14) -> 0
D15: 軽トラック | AE15: =SUM(E15:AD15) -> 0
B16: 2 | C16: 飛田 敬一 | D16: 日 当 | AE16: =SUM(E16:AD16) -> 0 | AF16: =AE16+AE17+AE18+AE19+AE20 -> 0
D17: 草 刈 機 | AE17: =SUM(E17:AD17) -> 0
D18: 畦畔草刈機 | AE18: =SUM(E18:AD18) -> 0
D19: 法面草刈機 | AE19: =SUM(E19:AD19) -> 0
D20: 軽トラック | AE20: =SUM(E20:AD20) -> 0
B21: 3 | D21: 日 当 | AE21: =SUM(E21:AD21) -> 0 | AF21: =AE21+AE22+AE23+AE24+AE25 -> 0
D22: 草 刈 機 | AE22: =SUM(E22:AD22) -> 0
D23: 畦畔草刈機 | AE23: =SUM(E23:AD23) -> 0
D24: 法面草刈機 | AE24: =SUM(E24:AD24) -> 0
D25: 軽トラック | AE25: =SUM(E25:AD25) -> 0
B26: 4 | D26: 日 当 | AE26: =SUM(E26:AD26) -> 0 | AF26: =AE26+AE27+AE28+AE29+AE30 -> 0
D27: 草 刈 機 | AE27: =SUM(E27:AD27) -> 0
D28: 畦畔草刈機 | AE28: =SUM(E28:AD28) -> 0
D29: 法面草刈機 | AE29: =SUM(E29:AD29) -> 0
D30: 軽トラック | AE30: =SUM(E30:AD30) -> 0
B31: 5 | D31: 日 当 | AE31: =SUM(E31:AD31) -> 0 | AF31: =AE31+AE32+AE33+AE34+AE35 -> 0
D32: 草 刈 機 | AE32: =SUM(E32:AD32) -> 0
D33: 畦畔草刈機 | AE33: =SUM(E33:AD33) -> 0
D34: 法面草刈機 | AE34: =SUM(E34:AD34) -> 0
D35: 軽トラック | AE35: =SUM(E35:AD35) -> 0
B36: 6 | D36: 日 当 | AE36: =SUM(E36:AD36) -> 0 | AF36: =AE36+AE37+AE38+AE39+AE40 -> 0
D37: 草 刈 機 | AE37: =SUM(E37:AD37) -> 0
D38: 畦畔草刈機 | AE38: =SUM(E38:AD38) -> 0
D39: 法面草刈機 | AE39: =SUM(E39:AD39) -> 0
D40: 軽トラック | AE40: =SUM(E40:AD40) -> 0
B41: 7 | D41: 日 当 | AE41: =SUM(E41:AD41) -> 0 | AF41: =AE41+AE42+AE43+AE44+AE45 -> 0
D42: 草 刈 機 | AE42: =SUM(E42:AD42) -> 0
...

Sheet 2.藤井
D2: 日当整理表 | G2: 農地維持
D3: 畦畔・農道・路肩・法面の草刈り等 | K3: 藤井 守 | O3: 令和７年度 | U3: 農・維２
B5: NO. | D5: 1 | E5: 2 | F5: 3 | G5: 4 | H5: 5 | I5: 6 | J5: 7 | K5: 8 | L5: 9 | M5: 10 | N5: 11 | O5: 12 | P5: 13 | Q5: 14 | R5: 15 | S5: 16 | T5: 17 | U5: 18 | V5: 19 | W5: 20 | Z5: 計
B6: 日 付 | D6: 4/5 | E6: 4/9 | F6: 4/12 | G6: 5/5 | H6: 5/7 | I6: 5/13 | J6: 5/22 | K6: 5/27 | L6: 6/4 | M6: 6/9 | N6: 6/21 | O6: 6/22 | P6: 6/25 | Q6: 7/5 | R6: 7/10 | S6: 7/12 | T6: 7/15 | U6: 7/18 | V6: 7/19 | W6: 7/21
B7: 時 間 帯 | D7: 0.33333333 | E7: 0.33333333 | F7: 0.29166667 | G7: 0.33333333 | H7: 0.29166667 | I7: 0.29166667 | J7: 0.375 | K7: 0.33333333 | L7: 0.54166667 | M7: 0.29166667 | N7: 0.625 | O7: 0.33333333 | P7: 0.58333333 | Q7: 0.66666667 | R7: 0.66666667 | S7: 0.375 | T7: 0.33333333 | U7: 0.625 | V7: 0.33333333 | W7: 0.33333333
D8: ～ | E8: ～ | F8: ～ | G8: ～ | H8: ～ | I8: ～ | J8: ～ | K8: ～ | L8: ～ | M8: ～ | N8: ～ | O8: ～ | P8: ～ | Q8: ～ | R8: ～ | S8: ～ | T8: ～ | U8: ～ | V8: ～ | W8: ～
D9: 0.41666667 | E9: 0.45833333 | F9: 0.41666667 | G9: 0.41666667 | H9: 0.375 | I9: 0.375 | J9: 0.45833333 | K9: 0.41666667 | L9: 0.625 | M9: 0.375 | N9: 0.70833333 | O9: 0.41666667 | P9: 0.66666667 | Q9: 0.75 | R9: 0.75 | S9: 0.41666667 | T9: 0.41666667 | U9: 0.75 | V9: 0.41666667 | W9: 0.41666667
B10: 実働時間 | D10: 2 | E10: 3 | F10: 3 | G10: 2 | H10: 2 | I10: 2 | J10: 2 | K10: 2 | L10: 2 | M10: 2 | N10: 2 | O10: 2 | P10: 2 | Q10: 2 | R10: 2 | S10: 2 | T10: 2 | U10: 3 | V10: 2 | W10: 2 | Z10: ４３時間
B11: 活動内容 | D11: 草刈り | E11: 草刈り | F11: 草刈り | G11: 草刈り | H11: 草刈り | I11: 草刈り | J11: 草刈り | K11: 草刈り | L11: 草刈り | M11: 草刈り | N11: 草刈り | O11: 草刈り | P11: 草刈り | Q11: 除草剤 散布 | R11: 除草剤 散布 | S11: 除草剤 散布 | T11: 草刈り | U11: 草刈り | V11: 草刈り | W11: 草刈り
B12: 日 当 | D12: 2000 | E12: 3000 | F12: 3000 | G12: 2000 | H12: 2000 | I12: 2000 | J12: 2000 | K12: 2000 | L12: 2000 | M12: 2000 | N12: 2000 | O12: 2000 | P12: 2000 | Q12: 2000 | R12: 2000 | S12: 2000 | T12: 2000 | U12: 3000 | V12: 2000 | W12: 2000 | Z12: =SUM(D12:Y12) -> 43000
B13: 機械名 | C13: 草 刈 機 | D13: 700 | E13: 350 | F13: 350 | G13: 700 | H13: 700 | I13: 700 | K13: 700 | L13: 700 | M13: 700 | N13: 700 | P13: 700 | U13: 700 | V13: 700 | Z13: =SUM(D13:Y13) -> 8400
C14: 畦畔草刈機 | E14: 1600 | F14: 1600 | J14: 1600 | O14: 1600 | T14: 1600 | U14: 800 | W14: 1600 | Z14: =SUM(D14:Y14) -> 10400
C15: 動力噴霧器 | Q15: 700 | R15: 700 | S15: 700 | Z15: =SUM(D15:Y15) -> 2100
C16: 軽トラック | Z16: =SUM(D16:Y16) -> 0
B17: 小 計 | D17: =SUM(D12:D16) -> 2700 | E17: =SUM(E12:E16) -> 4950 | F17: =SUM(F12:F16) -> 4950 | G17: =SUM(G12:G16) -> 2700 | H17: =SUM(H12:H16) -> 2700 | I17: =SUM(I12:I16) -> 2700 | J17: =SUM(J12:J16) -> 3600 | K17: =SUM(K12:K16) -> 2700 | ... W17: =SUM(W12:W16) -> 3600 | Z17: =SUM(D17:Y17) -> 63900
B19: NO. | D19: 21 | E19: 22 | F19: 23 | G19: 24 | H19: 25 | I19: 26 | J19: 27 | K19: 28 | L19: 29 | M19: 30 | N19: 31 | O19: 32 | P19: 33 | Q19: 34 | R19: 35 | S19: 36 | T19: 37 | U19: 38 | V19: 39 | W19: 40 | Z19: 計
B20: 日 付 | D20: 7/23 | E20: 7/25 | F20: 7/26 | G20: 8/1 | H20: 8/3 | I20: 8/20 | J20: 8/26 | K20: 8/27 | L20: 9/1 | M20: 9/2
B21: 時 間 帯 | D21: 0.54166667 | E21: 0.54166667 | F21: 0.33333333 | G21: 0.33333333 | H21: 0.33333333 | I21: 0.375 | J21: 0.33333333 | K21: 0.66666667 | L21: 0.29166667 | M21: 0.33333333
D22: ～ | E22: ～ | F22: ～ | G22: ～ | H22: ～ | I22: ～ | J22: ～ | K22: ～ | L22: ～ | M22: ～
D23: 0.625 | E23: 0.625 | F23: 0.41666667 | G23: 0.41666667 | H23: 0.41666667 | I23: 0.45833333 | J23: 0.41666667 | K23: 0.75 | L23: 0.375 | M23: 0.41666667
B24: 実働時間 | D24: 2 | E24: 2 | F24: 2 | G24: 2 | H24: 2 | I24: 2 | J24: 2 | K24: 2 | L24: 2 | M24: 2 | Z24: ２０時間
B25: 活動内容 | D25: 除草剤 散布 | E25: 除草剤 散布 | F25: 草刈り | G25: 草刈り | H25: 草刈り | I25: 草刈り | J25: 草刈り | K25: 草刈り | L25: 草刈り | M25: 草刈り
B26: 日 当 | D26: 2000 | E26: 2000 | F26: 2000 | G26: 2000 | H26: 2000 | I26: 2000 | J26: 2000 | K26: 2000 | L26: 2000 | M26: 2000 | Z26: =SUM(D26:Y26) -> 20000
B27: 機械名 | C27: 草 刈 機 | F27: 700 | J27: 700 | K27: 700 | L27: 700 | M27: 700 | Z27: =SUM(D27:Y27) -> 3500
C28: 畦畔草刈機 | G28: 1600 | H28: 1600 | I28: 1600 | Z28: =SUM(D28:Y28) -> 4800
C29: 動力噴霧器 | D29: 700 | E29: 700 | Z29: =SUM(D29:Y29) -> 1400
C30: 軽トラック | Z30: =SUM(D30:Y30) -> 0
B31: 小 計 | D31: =SUM(D26:D30) -> 2700 | E31: =SUM(E26:E30) -> 2700 | F31: =SUM(F26:F30) -> 2700 | G31: =SUM(G26:G30) -> 3600 | H31: =SUM(H26:H30) -> 3600 | I31: =SUM(I26:I30) -> 3600 | J31: =SUM(J26:J30) -> 2700 | K31: =SUM(K26:K30) -> 2700 | ... M31: =SUM(M26:M30) -> 2700 | Z31: =SUM(D31:Y31) -> 29700
AB32: 領収印
O33: 令和6年４月１日 改定 | R33: 日当 ： 1,00０円/時間 | W33: 日 当 合 計 | Y33: =Z12+Z26 -> 63000
P34: （各々燃料費を含む） | R34: 草刈機 ：＋３5０円円/時間 | W34: 機械借上げ合計 | Y34: =Z13+Z14+Z15+Z16+Z27+Z28+Z29+Z30 -> 30600
R35: 畦畔草刈機 ：＋８0０円円/時間 | W35: 支払額合計 | Y35: =Y33+Y34 -> 93600
R36: 軽トラック ：10００円/時間

Sheet 阿部正隆
D2: 日当整理表 | G2: 農地維持
D3: 畦畔・農道・路肩・法面の草刈り作業 | K3: 阿部正隆 | O3: 令和７年度 | V3: 農・維３
B5: NO. | D5: 1 | E5: 2 | F5: 3 | G5: 4 | H5: 5 | I5: 6 | J5: 7 | K5: 8 | L5: 9 | M5: 10 | N5: 11 | O5: 12 | P5: 13 | Q5: 14 | R5: 15 | S5: 16 | T5: 17 | U5: 18 | V5: 19 | W5: 20 | Z5: 計
B6: 日 付 | D6: 4/3 | E6: 4/4 | F6: 4/5 | G6: 4/8 | H6: 4/10 | I6: 4/15 | J6: 4/20 | K6: 4/25 | L6: 5/1 | M6: 5/3 | N6: 5/5 | O6: 5/8 | P6: 5/11 | Q6: 5/14 | R6: 5/17 | S6: 5/19 | T6: 6/1 | U6: 6/3 | V6: 6/5 | W6: 6/13
B7: 時 間 帯 | D7: 0.33333333 | E7: 0.33333333 | F7: 0.29166667 | G7: 0.54166667 | H7: 0.54166667 | I7: 0.29166667 | J7: 0.375 | K7: 0.33333333 | L7: 0.58333333 | M7: 0.29166667 | N7: 0.625 | O7: 0.33333333 | P7: 0.58333333 | Q7: 0.66666667 | R7: 0.66666667 | S7: 0.375 | T7: 0.33333333 | U7: 0.625 | V7: 0.33333333 | W7: 0.33333333
D8: ～ | E8: ～ | F8: ～ | G8: ～ | H8: ～ | I8: ～ | J8: ～ | K8: ～ | L8: ～ | M8: ～ | N8: ～ | O8: ～ | P8: ～ | Q8: ～ | R8: ～ | S8: ～ | T8: ～ | U8: ～ | V8: ～ | W8: ～
D9: 0.41666667 | E9: 0.41666667 | F9: 0.375 | G9: 0.625 | H9: 0.625 | I9: 0.375 | J9: 0.45833333 | K9: 0.41666667 | L9: 0.66666667 | M9: 0.375 | N9: 0.70833333 | O9: 0.41666667 | P9: 0.66666667 | Q9: 0.75 | R9: 0.75 | S9: 0.41666667 | T9: 0.41666667 | U9: 0.70833333 | V9: 0.41666667 | W9: 0.41666667
B10: 実働時間 | D10: 2 | E10: 2 | F10: 2 | G10: 2 | H10: 2 | I10: 2 | J10: 2 | K10: 2 | L10: 2 | M10: 2 | N10: 2 | O10: 2 | P10: 2 | Q10: 2 | R10: 2 | S10: 2 | T10: 2 | U10: 2 | V10: 2 | W10: 2 | Z10: ４０時間
B11: 活動内容 | D11: 草刈り | E11: 草刈り | F11: 草刈り | G11: 除草剤 散布 | H11: 除草剤 散布 | I11: 草刈り | J11: 草刈り | K11: 草刈り | L11: 草刈り | M11: 草刈り | N11: 草刈り | O11: 草刈り | P11: 草刈り | Q11: 除草剤 散布 | R11: 除草剤 散布 | S11: 除草剤 散布 | T11: 草刈り | U11: 草刈り | V11: 草刈り | W11: 草刈り
B12: 日 当 | D12: 2000 | E12: 2000 | F12: 2000 | G12: 2000 | H12: 2000 | I12: 2000 | J12: 2000 | K12: 2000 | L12: 2000 | M12: 2000 | N12: 2000 | O12: 2000 | P12: 2000 | Q12: 2000 | R12: 2000 | S12: 2000 | T12: 2000 | U12: 2000 | V12: 2000 | W12: 2000 | Z12: =SUM(D12:Y12) -> 40000
B13: 機械名 | C13: 草 刈 機 | D13: 700 | E13: 700 | F13: 700 | I13: 700 | K13: 700 | L13: 700 | M13: 700 | N13: 700 | P13: 700 | U13: 700 | Z13: =SUM(D13:Y13) -> 7000
C14: 畦畔草刈機 | J14: 1600 | O14: 1600 | T14: 1600 | V14: 1600 | W14: 1600 | Z14: =SUM(D14:Y14) -> 8000
C15: 動力噴霧器 | G15: 700 | H15: 700 | Q15: 700 | R15: 700 | S15: 700 | Z15: =SUM(D15:Y15) -> 3500
C16: 軽トラック | Z16: =SUM(D16:Y16) -> 0
B17: 小 計 | D17: =SUM(D12:D16) -> 2700 | E17: =SUM(E12:E16) -> 2700 | F17: =SUM(F12:F16) -> 2700 | G17: =SUM(G12:G16) -> 2700 | H17: =SUM(H12:H16) -> 2700 | I17: =SUM(I12:I16) -> 2700 | J17: =SUM(J12:J16) -> 3600 | K17: =SUM(K12:K16) -> 2700 | ... W17: =SUM(W12:W16) -> 3600 | Z17: =SUM(D17:Y17) -> 58500
B19: NO. | D19: 21 | E19: 22 | F19: 23 | G19: 24 | H19: 25 | I19: 26 | J19: 27 | K19: 28 | L19: 29 | M19: 30 | N19: 31 | O19: 32 | P19: 33 | Q19: 34 | R19: 35 | S19: 36 | T19: 37 | U19: 38 | V19: 39 | W19: 40 | Z19: 計
B20: 日 付 | D20: 6/18 | E20: 6/20 | F20: 6/25 | G20: 6/28 | H20: 6/29 | I20: 7/2 | J20: 7/7 | K20: 7/12 | L20: 7/16 | M20: 7/18 | N20: 7/25 | O20: 8/3 | P20: 8/6 | Q20: 8/10 | R20: 8/14 | S20: 8/20 | T20: 9/3 | U20: 9/7 | V20: 9/12
B21: 時 間 帯 | D21: 0.54166667 | E21: 0.33333333 | F21: 0.33333333 | G21: 0.33333333 | H21: 0.375 | I21: 0.33333333 | J21: 0.66666667 | K21: 0.29166667 | L21: 0.33333333 | M21: 0.33333333 | N21: 0.375 | O21: 0.29166667 | P21: 0.29166667 | Q21: 0.66666667 | R21: 0.66666667 | S21: 0.29166667 | T21: 0.33333333 | U21: 0.29166667 | V21: 0.33333333
D22: ～ | E22: ～ | F22: ～ | G22: ～ | H22: ～ | I22: ～ | J22: ～ | K22: ～ | L22: ～ | M22: ～ | N22: ～ | O22: ～ | P22: ～ | Q22: ～ | R22: ～ | S22: ～ | T22: ～ | U22: ～ | V22: ～
D23: 0.625 | E23: 0.41666667 | F23: 0.41666667 | G23: 0.41666667 | H23: 0.45833333 | I23: 0.41666667 | J23: 0.75 | K23: 0.375 | L23: 0.41666667 | M23: 0.41666667 | N23: 0.45833333 | O23: 0.375 | P23: 0.375 | Q23: 0.75 | R23: 0.75 | S23: 0.375 | T23: 0.41666667 | U23: 0.375 | V23: 0.41666667
B24: 実働時間 | D24: 2 | E24: 2 | F24: 2 | G24: 2 | H24: 2 | I24: 2 | J24: 2 | K24: 2 | L24: 2 | M24: 2 | N24: 2 | O24: 2 | P24: 2 | Q24: 2 | R24: 2 | S24: 2 | T24: 2 | U24: 2 | V24: 2 | Z24: ３８時間
B25: 活動内容 | D25: 除草剤 散布 | E25: 草刈り | F25: 草刈り | G25: 草刈り | H25: 草刈り | I25: 草刈り | J25: 草刈り | K25: 草刈り | L25: 草刈り | M25: 草刈り | N25: 草刈り | O25: 草刈り | P25: 草刈り | Q25: 草刈り | R25: 草刈り | S25: 草刈り | T25: 草刈り | U25: 草刈り | V25: 草刈り
B26: 日 当 | D26: 2000 | E26: 2000 | F26: 2000 | G26: 2000 | H26: 2000 | I26: 2000 | J26: 2000 | K26: 2000 | L26: 2000 | M26: 2000 | N26: 2000 | O26: 2000 | P26: 2000 | Q26: 2000 | R26: 2000 | S26: 2000 | T26: 2000 | U26: 2000 | V26: 2000 | Z26: =SUM(D26:Y26) -> 38000
B27: 機械名 | C27: 草 刈 機 | E27: 700 | G27: 700 | I27: 700 | J27: 700 | K27: 700 | L27: 700 | N27: 700 | O27: 700 | P27: 700 | Q27: 700 | R27: 700 | T27: 700 | U27: 700 | V27: 700 | Z27: =SUM(D27:Y27) -> 9800
C28: 畦畔草刈機 | F28: 1600 | H28: 1600 | M28: 1600 | S28: 1600 | Z28: =SUM(D28:Y28) -> 6400
C29: 動力噴霧器 | D29: 700 | Z29: =SUM(D29:Y29) -> 700
C30: 軽トラック | Z30: =SUM(D30:Y30) -> 0
B31: 小 計 | D31: =SUM(D26:D30) -> 2700 | E31: =SUM(E26:E30) -> 2700 | F31: =SUM(F26:F30) -> 3600 | G31: =SUM(G26:G30) -> 2700 | H31: =SUM(H26:H30) -> 3600 | I31: =SUM(I26:I30) -> 2700 | J31: =SUM(J26:J30) -> 2700 | K31: =SUM(K26:K30) -> 2700 | ... V31: =SUM(V26:V30) -> 2700 | Z31: =SUM(D31:Y31) -> 54900
O33: 令和6年４月１日 改定 | R33: 日当 ： 1,00０円/時間 | W33: 日 当 合 計 | Y33: =Z12+Z26 -> 78000
P34: （各々燃料費を含む） | R34: 草刈機 ：＋３5０円円/時間 | W34: 機械借上げ合計 | Y34: =Z13+Z14+Z15+Z16+Z27+Z28+Z29+Z30 -> 35400
R35: 畦畔草刈機 ：＋８0０円円/時間 | W35: 支払額合計 | Y35: =Y33+Y34 -> 113400
R36: 軽トラック ：10００円/時間
Y37: 領収印

Sheet 斉木忠義
D2: 日当整理表 | G2: 農地維持
D3: 畦畔・農道・路肩・法面の草刈り等 | K3: 斉木忠義 | O3: 令和７年度 | V3: 農・維４
B5: NO. | D5: 1 | E5: 2 | F5: 3 | G5: 4 | H5: 5 | I5: 6 | J5: 7 | K5: 8 | L5: 9 | M5: 10 | N5: 11 | O5: 12 | P5: 13 | Q5: 14 | R5: 15 | S5: 16 | T5: 17 | U5: 18 | V5: 19 | W5: 20 | Z5: 合計
B6: 日 付 | D6: 4/15 | E6: 5/6 | F6: 5/7 | G6: 5/9 | H6: 6/10 | I6: 7/12 | J6: 7/15 | K6: 7/18
B7: 時 間 帯 | D7: 0.33333333 | E7: 0.33333333 | F7: 0.375 | G7: 0.375 | H7: 0.33333333 | I7: 0.33333333 | J7: 0.29166667 | K7: 0.33333333
D8: ～ | E8: ～ | F8: ～ | G8: ～ | H8: ～ | I8: ～ | J8: ～ | K8: ～
D9: 0.41666667 | E9: 0.375 | F9: 0.41666667 | G9: 0.41666667 | H9: 0.375 | I9: 0.375 | J9: 0.33333333 | K9: 0.41666667
B10: 実働時間 | D10: 2 | E10: 1 | F10: 1 | G10: 1 | H10: 1 | I10: 1 | J10: 1 | K10: 2 | X10: １０時間
B11: 活動内容 | D11: 草刈り | E11: 草刈り | F11: 除草剤 散布 | G11: 除草剤 散布 | H11: 草刈り | I11: 草刈り | J11: 草刈り | K11: 草刈り
B12: 日 当 | D12: 2000 | E12: 1000 | F12: 1000 | G12: 1000 | H12: 1000 | I12: 1000 | J12: 1000 | K12: 2000 | Z12: =SUM(D12:Y12) -> 10000
B13: 機械名 | C13: 草 刈 機 | D13: 700 | E13: 350 | H13: 350 | I13: 350 | J13: 350 | K13: 700 | Z13: =SUM(D13:Y13) -> 2800
C14: 畦畔草刈機 | Z14: =SUM(D14:Y14) -> 0
C15: 動力噴霧器 | F15: 350 | G15: 350 | Z15: =SUM(D15:Y15) -> 700
C16: 軽トラック | Z16: =SUM(D16:Y16) -> 0
B17: 小 計 | D17: =SUM(D12:D16) -> 2700 | E17: =SUM(E12:E16) -> 1350 | F17: =SUM(F12:F16) -> 1350 | G17: =SUM(G12:G16) -> 1350 | H17: =SUM(H12:H16) -> 1350 | I17: =SUM(I12:I16) -> 1350 | J17: =SUM(J12:J16) -> 1350 | K17: =SUM(K12:K16) -> 2700 | Z17: =SUM(D17:Y17) -> 13500
B19: NO. | D19: 21 | E19: 22 | F19: 23 | G19: 24 | H19: 25 | I19: 26 | J19: 27 | K19: 28 | L19: 29 | M19: 30 | N19: 31 | O19: 32 | P19: 33 | Q19: 34 | R19: 35 | S19: 36 | T19: 37 | U19: 38 | V19: 39 | W19: 40 | Z19: 計
B20: 日 付
B21: 時 間 帯
B24: 実働時間
B25: 活動内容
B26: 日 当
B27: 機械名 | C27: 草 刈 機
C28: 畦畔草刈機
C29: 動力噴霧器
C30: 軽トラック
B31: 小 計 | D31: =SUM(D26:D30) -> 0 | E31: =SUM(E26:E30) -> 0 | F31: =SUM(F26:F30) -> 0 | G31: =SUM(G26:G30) -> 0 | H31: =SUM(H26:H30) -> 0 | I31: =SUM(I26:I30) -> 0 | J31: =SUM(J26:J30) -> 0 | K31: =SUM(K26:K30) -> 0 | ... M31: =SUM(M26:M30) -> 0
AB32: 領収印
O33: 令和6年４月１日 改定 | R33: 日当 ： 1,00０円/時間 | W33: 日 当 合 計 | Y33: =Z12+Z26 -> 10000
O34: （各々燃料費を含む） | R34: 草刈機 ：＋３5０円円/時間 | W34: 機械借上げ合計 | Y34: =Z13+Z14+Z15+Z16+Z27+Z28+Z29+Z30 -> 3500
R35: 畦畔草刈機 ：＋８0０円円/時間 | W35: 支払額合計 | Y35: =Y33+Y34 -> 13500
R36: 軽トラック ：10００円/時間

Sheet 下管理組合
B2: 日当等整理表
C3: 令和７年度 鎌田排水機場用地・農道・路肩の草刈り等 | M3: 鎌田下管理組合 | R3: 農・維５
B4: 参加者一覧 兼 領収印
C5: 氏 名 | D5: NO. | E5: 1 | F5: 2 | G5: 3 | H5: 4 | I5: 5 | J5: 6 | K5: 7 | L5: 8 | M5: 9 | N5: 10 | O5: 11 | P5: 12 | Q5: 13 | R5: 小計 | S5: 合 計 | T5: 領 収 印
D6: 日 付 | E6: 45788 | F6: 45797 | G6: 45799 | H6: 45803 | I6: 45812 | J6: 45822 | K6: 45822 | L6: 45837 | M6: 45839 | N6: 45881 | O6: 45901
D7: 時 間 帯 | E7: 0.33333333 | F7: 0.625 | G7: 0.41666667 | H7: 0.41666667 | I7: 0.375 | J7: 0.375 | K7: 0.58333333 | L7: 0.54166667 | M7: 0.33333333 | N7: 0.33333333 | O7: 0.375
E8: ～ | F8: ～ | G8: ～ | H8: ～ | I8: ～ | J8: ～ | K8: ～ | L8: ～ | M8: ～ | N8: ～ | O8: ～
E9: 0.41666667 | F9: 0.66666667 | G9: 0.5 | H9: 0.5 | I9: 0.41666667 | J9: 0.5 | K9: 0.625 | L9: 0.625 | M9: 0.41666667 | N9: 0.41666667 | O9: 0.54166667
D10: 実働時間 | E10: 2 | F10: 1 | G10: 2 | H10: 2 | I10: 1 | J10: 3 | K10: 1 | L10: 2 | M10: 2 | N10: 2 | O10: 2 | R10: 延べ ２７時間
D11: 活動内容 | E11: 草刈り モア機 | F11: 草刈り モア機 | G11: 草刈り モア機 | H11: 除草剤 散布 | I11: 草刈り | J11: 草刈り モア機 | K11: 草刈り | L11: 除草剤 散布 | M11: 草刈り | N11: 草刈り | O11: 草刈り モア機
B12: 1 | D12: 日 当 | E12: 2000 | G12: 2000 | J12: 3000 | R12: =SUM(E12:P12) -> 7000 | S12: =R12+R13 -> 7000
C13: 斉木 太郎 | D13: 草 刈 機 | R13: =SUM(E13:P13) -> 0
A14: 3143 | D14: 畦畔草刈機 | R14: 0
D15: 動力噴霧器
D16: 軽トラック | R16: 0
B17: 2 | D17: 日 当 | K17: 1000 | M17: 1000 | R17: =SUM(E17:P17) -> 2000 | S17: =R17+R18 -> 2700
C18: 藤井 守 | D18: 草 刈 機 | K18: 350 | M18: 350 | R18: =SUM(E18:P18) -> 700
D19: 畦畔草刈機 | R19: 0
D20: 動力噴霧器
D21: 軽トラック | R21: 0
B22: 3 | D22: 日 当 | F22: 1000 | H22: 2000 | I22: 1000 | K22: 1000 | L22: 2000 | M22: 2000 | N22: 2000 | O22: 2000 | R22: 13000 | S22: =R22+R23+R25 -> 16500
C23: 嘉藤 茂 | D23: 草 刈 機 | I23: 350 | K23: 350 | M23: 700 | N23: 700 | R23: =SUM(E23:P23) -> 2100
D24: 畦畔草刈機 | R24: 0
D25: 動力噴霧器 | H25: 700 | L25: 700 | R25: 1400
D26: 軽トラック | R26: 0
B27: 4 | D27: 日 当 | K27: 1000 | M27: 2000 | N27: 2000 | R27: =SUM(E27:P27) -> 5000 | S27: =R27+R28 -> 6750
C28: 渋谷 文啓 | D28: 草 刈 機 | K28: 350 | M28: 700 | N28: 700 | R28: =SUM(E28:P28) -> 1750
D29: 畦畔草刈機 | R29: 0
D30: 動力噴霧器
D31: 軽トラック | R31: 0
B33: 合 計 | C33: 日 当 | E33: =E12+E17+E22+E27 -> 2000 | F33: =F12+F17+F22+F27 -> 1000 | G33: =G12+G17+G22+G27 -> 2000 | H33: =H12+H17+H22+H27 -> 2000 | I33: =I12+I17+I22+I27 -> 1000 | J33: =J12+J17+J22+J27 -> 3000 | K33: =K12+K17+K22+K27 -> 3000 | L33: =L12+L17+L22+L27 -> 2000 | ... O33: =O12+O17+O22+O27 -> 2000 | R33: =SUM(E33:Q33) -> 27000 | S33: =R33+R34+R35+R36 -> 32950
C34: 機械名 | D34: 草 刈 機 | I34: 350 | K34: 1050 | M34: 1750 | N34: 1400 | R34: =SUM(E34:Q34) -> 4550
D35: 畦畔草刈機 | R35: =SUM(E35:P35) -> 0
D36: 動力噴霧器 | H36: 700 | L36: 700 | R36: 1400
D37: 軽トラック | R37: 0
J40: 令和6年４月１日 改定 | L40: 日当 ： 1,00０円/時間 | P40: =#REF!+#REF! -> #REF! | R40: 日 当 合 計 | T40: =R12+R17+R22+R27 -> 27000
L41: 草刈機 ：＋３5０円円/時間 | O41: モア機は（農）法人カマタより無償貸与 | R41: 機械借上げ合計 | T41: 5950
L42: 畦畔草刈機 ：＋８0０円円/時間 | R42: 支払額合計 | T42: =T40+T41 -> 32950
L43: 動力噴霧器 ：＋３５０円円/時間
L44: 軽トラック ：10００円/時間 | T44: =#REF!+#REF! -> #REF!
...

Sheet 一覧
C2: 一覧表
C3: 令和7年（自動入力） | G3: 令和元年 | H3: 令和２年 | I3: 令和３年 | J3: 令和４年 | K3: 令和６年 | M3: 法人 R７年 （自動入力）
C4: 法人カマタ | D4: =法人一覧!AD143 -> 415600 | F4: 417000 | G4: 440040 | H4: 441090 | I4: 446810 | J4: 445470 | K4: 446630 | M4: 斎木太郎 | N4: =法人一覧!AD11 -> 61450
C5: 藤井守 | D5: 93600 | G5: 58660 | H5: 65420 | I5: 64710 | J5: 64220 | K5: 65700 | M5: 阿部賢二 | N5: =法人一覧!AD24 -> 54900
C6: 飛田芳則 | G6: 39060 | H6: 32540 | I6: =#REF! -> #REF! | J6: 34020 | K6: 35100 | M6: 嘉藤茂 | N6: =法人一覧!AD37 -> 54000
C7: 小 計 | F7: 92000 | G7: 97720 | H7: =SUM(H5:H6) -> 97960 | I7: =I5+I6 -> #REF! | J7: =J5+J6 -> 98240 | K7: =SUM(K5:K6) -> 100800 | M7: 西谷博厚 | N7: =法人一覧!AD50 -> 40500
C8: 阿部正隆 | D8: =阿部正隆!Y35 -> 113400 | G8: 70260 | H8: 75230 | I8: 77130 | J8: 79890 | K8: 87650 | M8: 阿部知信 | N8: =法人一覧!AD82 -> 55350
C9: 古川/佐藤 | G9: 50400 | H9: 45360 | I9: 44100 | J9: 41580 | K9: 33400 | M9: 五十嵐修一 | N9: =法人一覧!AD95 -> 59400
C10: 小 計 | F10: 113000 | G10: 120660 | H10: =SUM(H8:H9) -> 120590 | I10: =I8+I9 -> 121230 | J10: =J8+J9 -> 121470 | K10: =SUM(K8:K9) -> 121050 | M10: 山田義雄 | N10: =法人一覧!AD108 -> 73800
C11: 斎木忠義 | D11: =斉木忠義!Y35 -> 13500 | F11: 13000 | G11: 13850 | H11: 13850 | I11: =#REF! -> #REF! | J11: 13860 | K11: 13950 | N11: =法人一覧!AD123 -> 16200
C12: 斎木昌樹 | G12: 1260 | H12: 0 | I12: 0 | J12: 0 | K12: 0 | M12: 穂刈和利 | N12: =法人一覧!#REF! -> #REF!
C13: 穂刈和利 | G13: 6300 | H13: 6300 | I13: 0 | J13: 0 | K13: 0 | N13: =法人一覧!#REF! -> #REF!
C14: 下管理組合 | D14: =下管理組合!T42 -> 32950 | F14: 33000 | G14: 33940 | H14: 35880 | I14: 35910 | J14: 35710 | K14: 36250 | N14: =法人一覧!#REF! -> #REF!
D15: =D4+D5+D8+D11+D14 -> 669050 | F15: =SUM(F4:F14) -> 668000 | G15: =G4+G7+G10+G11+G12+G13+G14 -> 713770 | H15: =H4+H7+H10+H11+H12+H13+H14 -> 715670 | I15: =I4+I7+I10+I11+I12+I13+I14 -> #REF! | J15: =J4+J7+J10+J11+J12+J13+J14 -> 714750 | K15: =K4+K7+K10+K11+K12+K13+K14 -> 718680 | N15: =SUM(N4:N14) -> #REF!
C17: 令和６年度比 | D17: 0.73

Sheet 元表
B1: 日当等整理表
C2: 農道・水路部分の草刈り作業
B3: 参加者一覧 兼 領収印
C4: 氏 名 | D4: NO. | E4: 1 | F4: 2 | G4: 3 | H4: 4 | I4: 5 | J4: 6 | K4: 7 | L4: 8 | M4: 9 | N4: 10 | O4: 11 | P4: 12 | Q4: 13 | R4: 14 | S4: 15 | T4: 16 | U4: 17 | V4: 18 | W4: 19 | X4: 20 | Y4: 21 | Z4: 22 | AA4: 23 | AB4: 24 | AC4: 25 | AD4: 26 | AE4: 小 計 | AF4: 合 計 | AG4: 領 収 印
D5: 日 付
D6: 時 間 帯
E7: ～ | F7: ～ | G7: ～ | H7: ～ | I7: ～ | J7: ～ | K7: ～ | L7: ～ | M7: ～ | N7: ～ | O7: ～ | P7: ～ | Q7: ～ | R7: ～ | S7: ～ | T7: ～ | U7: ～ | V7: ～ | W7: ～ | X7: ～ | Y7: ～ | Z7: ～ | AA7: ～ | AB7: ～ | AC7: ～ | AD7: ～
D9: 実働時間
D10: 活動内容
B11: 1 | D11: 日 当 | AE11: =SUM(E11:AD11) -> 0 | AF11: =AE11+AE12+AE13+AE14+AE15 -> 0
D12: 草 刈 機 | AE12: =SUM(E12:AD12) -> 0
D13: 畦畔草刈機 | AE13: =SUM(E13:AD13) -> 0
D14: 法面草刈機 | AE14: =SUM(E14:AD14) -> 0
D15: 軽トラック | AE15: =SUM(E15:AD15) -> 0
B16: 2 | D16: 日 当 | AE16: =SUM(E16:AD16) -> 0 | AF16: =AE16+AE17+AE18+AE19+AE20 -> 0
D17: 草 刈 機 | AE17: =SUM(E17:AD17) -> 0
D18: 畦畔草刈機 | AE18: =SUM(E18:AD18) -> 0
D19: 法面草刈機 | AE19: =SUM(E19:AD19) -> 0
D20: 軽トラック | AE20: =SUM(E20:AD20) -> 0
B21: 3 | D21: 日 当 | AE21: =SUM(E21:AD21) -> 0 | AF21: =AE21+AE22+AE23+AE24+AE25 -> 0
D22: 草 刈 機 | AE22: =SUM(E22:AD22) -> 0
D23: 畦畔草刈機 | AE23: =SUM(E23:AD23) -> 0
D24: 法面草刈機 | AE24: =SUM(E24:AD24) -> 0
D25: 軽トラック | AE25: =SUM(E25:AD25) -> 0
B26: 4 | D26: 日 当 | AE26: =SUM(E26:AD26) -> 0 | AF26: =AE26+AE27+AE28+AE29+AE30 -> 0
D27: 草 刈 機 | AE27: =SUM(E27:AD27) -> 0
D28: 畦畔草刈機 | AE28: =SUM(E28:AD28) -> 0
D29: 法面草刈機 | AE29: =SUM(E29:AD29) -> 0
D30: 軽トラック | AE30: =SUM(E30:AD30) -> 0
B31: 5 | D31: 日 当 | AE31: =SUM(E31:AD31) -> 0 | AF31: =AE31+AE32+AE33+AE34+AE35 -> 0
D32: 草 刈 機 | AE32: =SUM(E32:AD32) -> 0
D33: 畦畔草刈機 | AE33: =SUM(E33:AD33) -> 0
D34: 法面草刈機 | AE34: =SUM(E34:AD34) -> 0
D35: 軽トラック | AE35: =SUM(E35:AD35) -> 0
B36: 6 | D36: 日 当 | AE36: =SUM(E36:AD36) -> 0 | AF36: =AE36+AE37+AE38+AE39+AE40 -> 0
D37: 草 刈 機 | AE37: =SUM(E37:AD37) -> 0
D38: 畦畔草刈機 | AE38: =SUM(E38:AD38) -> 0
D39: 法面草刈機 | AE39: =SUM(E39:AD39) -> 0
D40: 軽トラック | AE40: =SUM(E40:AD40) -> 0
B41: 7 | D41: 日 当 | AE41: =SUM(E41:AD41) -> 0 | AF41: =AE41+AE42+AE43+AE44+AE45 -> 0
...
